Workbook
Name Angebotsart: [1]Definitionen!#REF!
Name Angebotsart: [1]Definitionen!#REF!
Name Angebotsart: [1]Definitionen!#REF!
Name Bezeichnung: "'Z18S2':'Z32S2'"
Name GPTA0_P2.9_I4: #REF!
Name GPTA0_P2.9_I4: #REF!
Name GTM_INT: #REF!
Name GTM_INT: #REF!
Name GTM_IO: #REF!
Name GTM_IO: #REF!
Name GTM_IRQ: #REF!
Name Prefix: [2]Definitions!#REF!
Name Prefix: [2]Definitions!#REF!
Name Prefix: [2]Definitions!#REF!
Name Pulldown: [2]Definitions!#REF!
Name Pulldown: [2]Definitions!#REF!
Name Pulldown: [2]Definitions!#REF!
Name SOP: '[1]2. Projekt Technik'!#REF!
Name SOP: '[1]2. Projekt Technik'!#REF!
Name Szenario: '[1]2. Projekt Technik'!#REF!
Name Szenario: '[1]2. Projekt Technik'!#REF!
Name Variant: #REF!
Name Variant: #REF!

Sheet ChangeHistory
A1: File-Information
A3: Processor Type | B3: TC275T
A4: Template Version | B4: 1
A6: Project-Name
A7: Customer | B7: TBD
A8: EA-Number
A10: This file represents the interface between hard- and software for a certain project.
A11: Please enter all data completely and carefully.
A12: Anything not requested won't appear in the port assignment!
A14: List Of Changes
A16: Item No. | B16: Date | C16: Name | D16: Comment
A17: 1 | B17: 08/28/2012 | C17: Trempert | D17: Abgeleitet von Version: Ports_Inverter_Gen3_Device3_ELMAR_Plattform_Prototyp.xls Mit Item No.12
A18: 2 | B18: 41172 | C18: Prathap Singh (RBEI/EEH2) | D18: First draft of assignment created.
A19: 3 | B19: 41183 | C19: Eiben | D19: Info Mark Damson: changed P21.0, P21.1,P21.3,P21.4 from TOM to ATOM and P21.3 from ATOM to TOM
A20: 4 | B20: 41219 | C20: Prathap Singh (RBEI/EEH2) Trempert Chris (GS-EH/EPC3) | D20: Signal name changes: - CTO_EN2_B1 (P10_1) --> CTO_EN3_B1 (P10_1); - CTO_STB2_B2 (P10_2) --> CTO_STB3_B2 (P10_2); - CTO_ERR2_B2_MON (P33_1) --> CTO_ERR3_B2_MON (P33_1) ; - CTO_WAKE2_B1_MON (P33_0) --> CTO_WAKE3_B1_MON (P33_0) - CTO_EN1 (P2_4) --> CTO_EN2 (P2_4) - CTO_STB1 (P2_5) --> CTO_STB2 (P2_5) - CTO_ERR1_B0 (P10_7) --> CTO_ERR2_B0 (P10_7) - CTO_WAKE1 (P2_6) --> CTO_WAKE2 (P2_6)
A21: 5 | B21: 41282 | C21: Navin Kumar (RBEI/EEH2) | D21: - Updated driver strength
A22: 6 | B22: 41285 | C22: Trempert Chris (GS-EH/EPC3) Navin Kumar (RBEI/EEH2) | D22: - Changed the driver strength as per mail dated 01/10/2013 from Mr.Trempert Chris
A23: 17 | B23: 41348 | C23: Eiben, Frank | D23: - changed CLK_CPLD_DO from EXTCLK0 to GTMCLK0
A24: 1 | B24: 41358 | C24: Trempert Chris (GS-EH/EPE1) Gurumahantesh (RBEI/EEH2) | D24: Initial version of assignment created based on : Ports_Inverter_Gen3_Device3_ELMAR35_INVCON3.3_VW_Audi as per mail from Mr.Trempert dated - 13-03-2013.
A25: 2 | B25: 41382 | C25: Prathap Singh (RBEI/EEH2) | D25: - HBHP1_DO --> inclusion of ATOM0_0 under "GTM-int" column - RXD_NVuC_TXD_HVuC --> inclusion of TIM3_0 as it is needed to capture the timestamp along with the regular UART functionality - ADC_Trigger_DO --> inclusion of ATOM1_1 and ATOM1_0
A26: 3 | B26: 41397 | C26: Trempert Chris (GS-EH/EPE1) Navin Kumar (RBEI/EEH2) | D26: - Driver strengths are updated for some of the signals
A27: 4 | B27: 41431 | C27: Navin Kumar (RBEI/EEH2) | D27: - ADC namings updated in the template
A28: 5 | B28: 41466 | C28: Prathap Singh (RBEI/EEH2) Kirschner Manfred (GS-EH/EPE1) | D28: Creation of C-Sample with reference to B-Sample assignment: - RES_DI_AIN – added “I” to indicate it is a GPIO Input signal - NERROR_Pin – TIM0_4 not needed and removed - TRQ_EN_DI – TIM0_5 not needed as it is GPIO input - EMTMP_CTRL_DO – pin config changed from “U-T” to “WEAK” - B1/2/3_DI - pin config changed from “U-T” to “F-T”
A29: 6 | B29: 41470 | C29: Kirschner Manfred (GS-EH/EPE1) Prathap Singh (RBEI/EEH2) | D29: - RES_DI_AIN - signal deleted - NWDA - signal deleted - CPLD_RES2_DI, CPLD_RES3_DI, CPLD_RES4_DI - signals deleted - RSV_NENEXTHI_DO - new signal assinged at P32.2 - RSV_NENEXTLO_DO - new signal assigned at P32.3 - VOGT_DIAG_DO - new signal assigned at P13.0 - VOGT_DIAG_AIN - new signal assigned at AN35 - CTO_NSTB - new signal assigned at P02.6 - RSV_COSLO_AIN - pin config chanegd from U - T to F – T - RSV_EXTLO_DO - pin config changed from WEAK to MED
... A36: 13 | B36: 41583 | C36: Kirschner Manfred (GS-EH/EPE1) Abhishek S R(RBEI/EEH2) | D36: changes are as per mail dated Di 22.10.2013 12:52 - RSTGTRL_DO and RSTGTRH_DO renamed in CPLD_RES2_DI and CPLD_RES3_DI, pin config for all CPLD_RESx changed to "U-T" - SLSO06_CY327 (P20.10) moved to SLSO02_CY327 (P20.13) - SLSO02_FLR_EN (P20.13) moved to SLSO06_FLR_EN (P20.10) - KL31_SENSE_AIN, VDD5G3_AIN deleted - vWhiRe renamed to vWhlRi_DI - vWhiLe renamed to vWhlLe_DI - NERROR Pin renamed to NERROR - SD_VDD3V3_DCW_DO pin config changed from "WEAK" to "MED" - Pin config B0_DI, B1_DI, B2_DI is "U-T" because not used in series ECU
A37: V0.0 | B37: 43439 | C37: ZXC,ZWB,LYH | D37: First version
A38: V1.0 | B38: 43453 | C38: LYH

Sheet HSI
B2: HSI_INVxxxx
B3: TC275 (LQFP)
B4: Author: | C4: XXX
B5: Dept:
B6: Date:
B7: General | N7: HW Confirm | P7: SW Confirm
B8: Signal Name | C8: HW Name Netlist | D8: ShortName | E8: Pin Num | F8: Pin Name | G8: Change | H8: uC Fun | I8: Dir | J8: ASIL | K8: State | L8: Filter | M8: 功能描述 | N8: Accept | O8: Comment | P8: Accept | Q8: Comment
B9: Analog Inputs
B10: IU_A_AI | C10: IU_A_AN32 | D10: IUA | E10: 38 | F10: =INDIRECT("REF!B"&MATCH(E10,REF!A:A,0)) -> AN32 | G10: N | H10: VADC | I10: A | J10: A | L10: <5us | M10: Level1相电流采集1, G4CH0 | N10: Accept | P10: Reject
B11: IV_A_AI | C11: IV_A_AN44 | D11: IVA | E11: 31 | F11: =INDIRECT("REF!B"&MATCH(E11,REF!A:A,0)) -> AN44 | G11: N | H11: VADC | I11: A | J11: A | L11: <5us | M11: Level1相电流采集2, G5CH4 | N11: Accept | P11: Reject
B12: IW_A_AI | C12: IW_A_AN48 | D12: IWA | E12: 23 | F12: =INDIRECT("REF!B"&MATCH(E12,REF!A:A,0)) -> AN48 | G12: N | H12: VADC | I12: A | J12: A | K12: tri-state | L12: <5us | M12: Level1相电流采集3, Port端口定义为三态, G6CH0 | N12: Accept | P12: Reject
B13: IU_B_AI | C13: IU_B_AN49 | D13: IUB | E13: 22 | F13: =INDIRECT("REF!B"&MATCH(E13,REF!A:A,0)) -> AN49 | G13: N | H13: VADC | I13: A | J13: C | K13: tri-state | L13: <5us | M13: Level2相电流采集1, Port端口定义为三态, G6CH1 | N13: Accept | P13: Reject
B14: IV_B_AI | C14: IV_B_AN33 | D14: IVB | E14: 37 | F14: =INDIRECT("REF!B"&MATCH(E14,REF!A:A,0)) -> AN33 | G14: N | H14: VADC | I14: A | J14: C | L14: <5us | M14: Level2相电流采集2, G4CH1 | N14: Accept | P14: Reject
B15: IW_B_AI | C15: IW_B_AN45 | D15: IWB | E15: 30 | F15: =INDIRECT("REF!B"&MATCH(E15,REF!A:A,0)) -> AN45 | G15: N | H15: VADC | I15: A | J15: C | L15: <5us | M15: Level2相电流采集3, G5CH5 | N15: Accept | P15: Reject
B16: EXCP_DS1_AI | C16: EXCP_DS1_AN0 | D16: EXCP | E16: 67 | F16: =INDIRECT("REF!B"&MATCH(E16,REF!A:A,0)) -> AN0 | G16: N | H16: DSADC | I16: A | J16: A | K16: ` | L16: <5us | M16: 旋变软解码level1激励差分信号采集，需要分压给MCU. 触发TIM时间捕捉，TIM1_0. DSADC1 | N16: Accept | P16: Reject
B17: EXCN_DS1_AI | C17: EXCN_DS1_AN1 | D17: EXCN | E17: 66 | F17: =INDIRECT("REF!B"&MATCH(E17,REF!A:A,0)) -> AN1 | G17: N | H17: DSADC | I17: A | J17: A | L17: <5us | N17: Accept | P17: Reject
B18: SINP_DS0_AI | C18: SINP_DS0_AN2 | D18: SINP | E18: 65 | F18: =INDIRECT("REF!B"&MATCH(E18,REF!A:A,0)) -> AN2 | G18: N | H18: DSADC | I18: A | J18: A | L18: <5us | M18: 旋变软解码level1反馈信号SIN差分信号采集. DSADC0 | N18: Accept | P18: Reject
B19: SINN_DS0_AI | C19: SINN_DS0_AN3 | D19: SINN | E19: 64 | F19: =INDIRECT("REF!B"&MATCH(E19,REF!A:A,0)) -> AN3 | G19: N | H19: DSADC | I19: A | J19: A | L19: <5us | N19: Accept | P19: Reject
B20: COSP_DS2_AI | C20: COSP_DS2_AN20 | D20: COSP | E20: 46 | F20: =INDIRECT("REF!B"&MATCH(E20,REF!A:A,0)) -> AN20 | G20: N | H20: DSADC | I20: A | J20: A | L20: <5us | M20: 旋变软解码level1反馈信号COS差分信号采集.DSADC2 | N20: Accept | P20: Reject
B21: COSN_DS2_AI | C21: COSN_DS2_AN21 | D21: COSN | E21: 45 | F21: =INDIRECT("REF!B"&MATCH(E21,REF!A:A,0)) -> AN21 | G21: N | H21: DSADC | I21: A | J21: A | L21: <5us | N21: Accept | P21: Reject
B22: SINH_AI | C22: SINH_AN4 | D22: SINH | E22: 63 | F22: =INDIRECT("REF!B"&MATCH(E22,REF!A:A,0)) -> AN4 | G22: N | H22: VADC | I22: A | J22: C | L22: <5us | M22: 旋变软解码level2反馈信号SIN+信号, G0CH4 | N22: Accept | P22: Reject
B23: SINL_AI | C23: SINL_AN8 | D23: SINL | E23: 59 | F23: =INDIRECT("REF!B"&MATCH(E23,REF!A:A,0)) -> AN8 | G23: N | H23: VADC | I23: A | J23: C | L23: <5us | M23: 旋变软解码level2反馈信号SIN-信号, G1CH0 | N23: Accept | P23: Reject
B24: COSH_AI | C24: COSH_AN16 | D24: COSH | E24: 50 | F24: =INDIRECT("REF!B"&MATCH(E24,REF!A:A,0)) -> AN16 | G24: N | H24: VADC | I24: A | J24: C | L24: <5us | M24: 旋变软解码level2反馈信号COS+信号, G2CH0 | N24: Accept | P24: Reject
B25: COSL_AI | C25: COSL_AN24 | D25: COSL | E25: 44 | F25: =INDIRECT("REF!B"&MATCH(E25,REF!A:A,0)) -> AN24 | G25: N | H25: VADC | I25: A | J25: C | L25: <5us | M25: 旋变软解码level2反馈信号COS-信号, G3CH0 | N25: Accept | P25: Reject
B26: HVUP_AI | C26: HVUP_AN17 | D26: HVUP | E26: 49 | F26: =INDIRECT("REF!B"&MATCH(E26,REF!A:A,0)) -> AN17 | G26: N | H26: VADC | I26: A | J26: A | L26: <10us | M26: 高压母线电压采集正。通过隔离线性光耦, G2CH1 | N26: Accept | P26: Reject
B27: HVUN_AI | C27: HVUN_AN25 | D27: HVUN | E27: 43 | F27: =INDIRECT("REF!B"&MATCH(E27,REF!A:A,0)) -> AN25 | G27: N | H27: VADC | I27: A | J27: A | L27: <10us | M27: 高压母线电压采集负，通过隔离线性光耦, G3CH1 | N27: Accept | P27: Reject
B28: UBR1_AI | C28: UBR1_AN5 | D28: UBR1 | E28: 62 | F28: =INDIRECT("REF!B"&MATCH(E28,REF!A:A,0)) -> AN5 | G28: Y | H28: VADC | I28: A | J28: A | L28: <1ms | M28: 12V电池电压采集 | N28: Accept | P28: Reject
B29: UBR2_AI | C29: UBR2_AN37 | D29: UBR2 | E29: 34 | F29: =INDIRECT("REF!B"&MATCH(E29,REF!A:A,0)) -> AN37 | G29: Y | H29: VADC | I29: A | J29: A | L29: <1ms | M29: 第二路12V电池电压采集, 斜率要求与第一路不能一样 | N29: Accept | P29: Reject
B30: ADCTEST_AI | C30: ADCTEST_AN35 | D30: ADCTEST | E30: 36 | F30: =INDIRECT("REF!B"&MATCH(E30,REF!A:A,0)) -> AN35 | G30: Y | H30: VADC | I30: A | J30: A | L30: <1ms | M30: PDD, pull-down device for pull-down diagnostics, 2.5V | N30: Accept | P30: Reject
B31: VDD15_AI | C31: VDD15_AN47 | D31: VDD15 | E31: 28 | F31: =INDIRECT("REF!B"&MATCH(E31,REF!A:A,0)) -> AN47 | G31: Y | H31: VADC | I31: A | J31: A | L31: <1ms | M31: 驱动16V电压信号回采 | N31: Accept | P31: Reject
B32: MTEM1_AI | C32: MTEM1_AN11 | D32: MTEM1 | E32: 57 | F32: =INDIRECT("REF!B"&MATCH(E32,REF!A:A,0)) -> AN11 | G32: Y | H32: VADC | I32: A | J32: A | L32: <5ms | M32: 电机定子温度1采集 | N32: Accept | P32: Reject
B33: MTEM2_AI | C33: MTEM2_AN13 | D33: MTEM2 | E33: 55 | F33: =INDIRECT("REF!B"&MATCH(E33,REF!A:A,0)) -> AN13 | G33: Y | H33: VADC | I33: A | J33: A | L33: <5ms | M33: 电机定子温度2采集 | N33: Accept | P33: Reject
... B37: HWVER_AI | C37: HWVER_AN38 | D37: HWVER | E37: 33 | F37: =INDIRECT("REF!B"&MATCH(E37,REF!A:A,0)) -> AN38 | G37: Y | H37: VADC | I37: A | J37: A | L37: <1ms | M37: 硬件版本信息G4CH5 | N37: Accept | P37: Reject
N38: Reject | P38: Reject
B39: PWM Outputs/Inputs
B40: PWMTRG_O | C40: PWMTRG_P02_8 | D40: PWMTRG | E40: 9 | F40: =INDIRECT("REF!B"&MATCH(E40,REF!A:A,0)) -> P02.8 | G40: N | H40: ATOM0_0 | I40: O | J40: A | L40: NA | M40: 软件预留，外接测试焊盘: ATOM0_0, TIM2_0，连接到P00.0 | N40: Reject | P40: Reject
B41: PU | C41: PU_P02_1 | D41: PU | E41: 2 | F41: =INDIRECT("REF!B"&MATCH(E41,REF!A:A,0)) -> P02.1 | G41: N | H41: ATOM0_1 | I41: O | J41: A | L41: NA | M41: IGBT驱动信号,ATOM0_1 | N41: Reject | P41: Reject
B42: PV | C42: PV_P02_2 | D42: PV | E42: 3 | F42: =INDIRECT("REF!B"&MATCH(E42,REF!A:A,0)) -> P02.2 | G42: N | H42: ATOM0_2 | I42: O | J42: A | L42: NA | M42: IGBT驱动信号,ATOM0_2 | N42: Reject | P42: Reject
B43: PW | C43: PW_P02_3 | D43: PW | E43: 4 | F43: =INDIRECT("REF!B"&MATCH(E43,REF!A:A,0)) -> P02.3 | G43: N | H43: ATOM0_3 | I43: O | J43: A | L43: NA | M43: IGBT驱动信号,ATOM0_3 | N43: Reject | P43: Reject
B44: PX | C44: PX_P02_4 | D44: PX | E44: 5 | F44: =INDIRECT("REF!B"&MATCH(E44,REF!A:A,0)) -> P02.4 | G44: N | H44: ATOM0_4 | I44: O | J44: A | L44: NA | M44: IGBT驱动信号,ATOM0_4 | N44: Reject | P44: Reject
...

Sheet REF
A1: PinNumber | B1: PinName | C1: Signal Name | D1: 备注
A2: 1 | B2: P02.0 | C2: =IFERROR(INDIRECT("HSI!B"&MATCH(A2,HSI!E:E,0)),"N.C.") -> NFLTAH | D2: Signal Name由HSI链接过来
A3: 2 | B3: P02.1 | C3: =IFERROR(INDIRECT("HSI!B"&MATCH(A3,HSI!E:E,0)),"N.C.") -> PU
A4: 3 | B4: P02.2 | C4: =IFERROR(INDIRECT("HSI!B"&MATCH(A4,HSI!E:E,0)),"N.C.") -> PV
A5: 4 | B5: P02.3 | C5: =IFERROR(INDIRECT("HSI!B"&MATCH(A5,HSI!E:E,0)),"N.C.") -> PW
A6: 5 | B6: P02.4 | C6: =IFERROR(INDIRECT("HSI!B"&MATCH(A6,HSI!E:E,0)),"N.C.") -> PX
A7: 6 | B7: P02.5 | C7: =IFERROR(INDIRECT("HSI!B"&MATCH(A7,HSI!E:E,0)),"N.C.") -> PY
A8: 7 | B8: P02.6 | C8: =IFERROR(INDIRECT("HSI!B"&MATCH(A8,HSI!E:E,0)),"N.C.") -> PZ
A9: 8 | B9: P02.7 | C9: =IFERROR(INDIRECT("HSI!B"&MATCH(A9,HSI!E:E,0)),"N.C.") -> NESO
A10: 9 | B10: P02.8 | C10: =IFERROR(INDIRECT("HSI!B"&MATCH(A10,HSI!E:E,0)),"N.C.") -> PWMTRG_O
A11: 10 | B11: VDD/VDDSB | C11: VDD1V3 | D11: Signal Name为手动输入
A12: 11 | B12: P00.0 | C12: =IFERROR(INDIRECT("HSI!B"&MATCH(A12,HSI!E:E,0)),"N.C.") -> PWMTRG | D12: Signal Name由HSI链接过来
A13: 12 | B13: P00.1 | C13: =IFERROR(INDIRECT("HSI!B"&MATCH(A13,HSI!E:E,0)),"N.C.") -> N.C.
A14: 13 | B14: P00.2 | C14: =IFERROR(INDIRECT("HSI!B"&MATCH(A14,HSI!E:E,0)),"N.C.") -> N.C.
A15: 14 | B15: P00.3 | C15: =IFERROR(INDIRECT("HSI!B"&MATCH(A15,HSI!E:E,0)),"N.C.") -> ADC2TRG
A16: 15 | B16: P00.4 | C16: =IFERROR(INDIRECT("HSI!B"&MATCH(A16,HSI!E:E,0)),"N.C.") -> NFLTAL
A17: 16 | B17: P00.5 | C17: =IFERROR(INDIRECT("HSI!B"&MATCH(A17,HSI!E:E,0)),"N.C.") -> NFLTBL
A18: 17 | B18: P00.6 | C18: =IFERROR(INDIRECT("HSI!B"&MATCH(A18,HSI!E:E,0)),"N.C.") -> DOUTX
A19: 18 | B19: P00.7 | C19: =IFERROR(INDIRECT("HSI!B"&MATCH(A19,HSI!E:E,0)),"N.C.") -> DOUTY
A20: 19 | B20: P00.8 | C20: =IFERROR(INDIRECT("HSI!B"&MATCH(A20,HSI!E:E,0)),"N.C.") -> DOUTZ
A21: 20 | B21: P00.9 | C21: =IFERROR(INDIRECT("HSI!B"&MATCH(A21,HSI!E:E,0)),"N.C.") -> N.C.
A22: 21 | B22: P00.10 | C22: =IFERROR(INDIRECT("HSI!B"&MATCH(A22,HSI!E:E,0)),"N.C.") -> N.C.
A23: 22 | B23: AN49 | C23: =IFERROR(INDIRECT("HSI!B"&MATCH(A23,HSI!E:E,0)),"N.C.") -> IU_B_AI
A24: 23 | B24: AN48 | C24: =IFERROR(INDIRECT("HSI!B"&MATCH(A24,HSI!E:E,0)),"N.C.") -> IW_A_AI
A25: 24 | B25: VDD | C25: VDD1V3 | D25: Signal Name为手动输入
A26: 25 | B26: VEXT | C26: VDD5
A27: 26 | B27: VAREF2 | C27: VAREF2
A28: 27 | B28: VAGND2 | C28: GND
A29: 28 | B29: AN47 | C29: =IFERROR(INDIRECT("HSI!B"&MATCH(A29,HSI!E:E,0)),"N.C.") -> VDD15_AI | D29: Signal Name由HSI链接过来
A30: 29 | B30: AN46 | C30: =IFERROR(INDIRECT("HSI!B"&MATCH(A30,HSI!E:E,0)),"N.C.") -> N.C.
A31: 30 | B31: AN45 | C31: =IFERROR(INDIRECT("HSI!B"&MATCH(A31,HSI!E:E,0)),"N.C.") -> IW_B_AI
A32: 31 | B32: AN44 | C32: =IFERROR(INDIRECT("HSI!B"&MATCH(A32,HSI!E:E,0)),"N.C.") -> IV_A_AI
A33: 32 | B33: AN39 | C33: =IFERROR(INDIRECT("HSI!B"&MATCH(A33,HSI!E:E,0)),"N.C.") -> N.C.
A34: 33 | B34: AN38 | C34: =IFERROR(INDIRECT("HSI!B"&MATCH(A34,HSI!E:E,0)),"N.C.") -> HWVER_AI
A35: 34 | B35: AN37 | C35: =IFERROR(INDIRECT("HSI!B"&MATCH(A35,HSI!E:E,0)),"N.C.") -> UBR2_AI
A36: 35 | B36: AN36 | C36: =IFERROR(INDIRECT("HSI!B"&MATCH(A36,HSI!E:E,0)),"N.C.") -> RES3
A37: 36 | B37: AN35 | C37: =IFERROR(INDIRECT("HSI!B"&MATCH(A37,HSI!E:E,0)),"N.C.") -> ADCTEST_AI
A38: 37 | B38: AN33 | C38: =IFERROR(INDIRECT("HSI!B"&MATCH(A38,HSI!E:E,0)),"N.C.") -> IV_B_AI
A39: 38 | B39: AN32 | C39: =IFERROR(INDIRECT("HSI!B"&MATCH(A39,HSI!E:E,0)),"N.C.") -> IU_A_AI
A40: 39 | B40: AN29 | C40: =IFERROR(INDIRECT("HSI!B"&MATCH(A40,HSI!E:E,0)),"N.C.") -> N.C.
...

Sheet TC275
C2: Level1 | E2: Level2 | G2: Level3 | I2: Power
A11: 1 | B11: =IFERROR(INDIRECT("REF!C"&MATCH(A11,REF!A:A,0)),"N.C.") -> NFLTAH | S11: =IFERROR(INDIRECT("REF!C"&MATCH(T11,REF!A:A,0)),"N.C.") -> SBC_MTSR0 | T11: 132 | V11: 45 | W11: =IFERROR(INDIRECT("REF!C"&MATCH(V11,REF!A:A,0)),"N.C.") -> COSN_DS2_AI | AN11: =IFERROR(INDIRECT("REF!C"&MATCH(AO11,REF!A:A,0)),"N.C.") -> NFLTBH | AO11: 176
A12: 2 | B12: =IFERROR(INDIRECT("REF!C"&MATCH(A12,REF!A:A,0)),"N.C.") -> PU | S12: =IFERROR(INDIRECT("REF!C"&MATCH(T12,REF!A:A,0)),"N.C.") -> SBC_CS002 | T12: 131 | V12: 46 | W12: =IFERROR(INDIRECT("REF!C"&MATCH(V12,REF!A:A,0)),"N.C.") -> COSP_DS2_AI | AN12: =IFERROR(INDIRECT("REF!C"&MATCH(AO12,REF!A:A,0)),"N.C.") -> N.C. | AO12: 175
A13: 3 | B13: =IFERROR(INDIRECT("REF!C"&MATCH(A13,REF!A:A,0)),"N.C.") -> PV | S13: =IFERROR(INDIRECT("REF!C"&MATCH(T13,REF!A:A,0)),"N.C.") -> SBC_MRST0 | T13: 130 | V13: 47 | W13: =IFERROR(INDIRECT("REF!C"&MATCH(V13,REF!A:A,0)),"N.C.") -> VDD5_AI | AN13: =IFERROR(INDIRECT("REF!C"&MATCH(AO13,REF!A:A,0)),"N.C.") -> HWCFG5 | AO13: 174
A14: 4 | B14: =IFERROR(INDIRECT("REF!C"&MATCH(A14,REF!A:A,0)),"N.C.") -> PW | S14: =IFERROR(INDIRECT("REF!C"&MATCH(T14,REF!A:A,0)),"N.C.") -> SBC_CLK0 | T14: 129 | V14: 48 | W14: =IFERROR(INDIRECT("REF!C"&MATCH(V14,REF!A:A,0)),"N.C.") -> VDD5G1_AI | AN14: =IFERROR(INDIRECT("REF!C"&MATCH(AO14,REF!A:A,0)),"N.C.") -> HWCFG4 | AO14: 173
A15: 5 | B15: =IFERROR(INDIRECT("REF!C"&MATCH(A15,REF!A:A,0)),"N.C.") -> PX | S15: =IFERROR(INDIRECT("REF!C"&MATCH(T15,REF!A:A,0)),"N.C.") -> N.C. | T15: 128 | V15: 49 | W15: =IFERROR(INDIRECT("REF!C"&MATCH(V15,REF!A:A,0)),"N.C.") -> HVUP_AI | AN15: =IFERROR(INDIRECT("REF!C"&MATCH(AO15,REF!A:A,0)),"N.C.") -> N.C. | AO15: 172
A16: 6 | B16: =IFERROR(INDIRECT("REF!C"&MATCH(A16,REF!A:A,0)),"N.C.") -> PY | S16: =IFERROR(INDIRECT("REF!C"&MATCH(T16,REF!A:A,0)),"N.C.") -> WDI | T16: 127 | V16: 50 | W16: =IFERROR(INDIRECT("REF!C"&MATCH(V16,REF!A:A,0)),"N.C.") -> COSH_AI | AN16: =IFERROR(INDIRECT("REF!C"&MATCH(AO16,REF!A:A,0)),"N.C.") -> DFDN_H | AO16: 171
A17: 7 | B17: =IFERROR(INDIRECT("REF!C"&MATCH(A17,REF!A:A,0)),"N.C.") -> PZ | S17: =IFERROR(INDIRECT("REF!C"&MATCH(T17,REF!A:A,0)),"N.C.") -> CRASH | T17: 126 | V17: 51 | W17: =IFERROR(INDIRECT("REF!C"&MATCH(V17,REF!A:A,0)),"N.C.") -> GND | AN17: =IFERROR(INDIRECT("REF!C"&MATCH(AO17,REF!A:A,0)),"N.C.") -> DFUP_L | AO17: 170
A18: 8 | B18: =IFERROR(INDIRECT("REF!C"&MATCH(A18,REF!A:A,0)),"N.C.") -> NESO | S18: =IFERROR(INDIRECT("REF!C"&MATCH(T18,REF!A:A,0)),"N.C.") -> ENSMPS | T18: 125 | V18: 52 | W18: =IFERROR(INDIRECT("REF!C"&MATCH(V18,REF!A:A,0)),"N.C.") -> VAREF1 | AN18: =IFERROR(INDIRECT("REF!C"&MATCH(AO18,REF!A:A,0)),"N.C.") -> DFDN_L | AO18: 169
A19: 9 | B19: =IFERROR(INDIRECT("REF!C"&MATCH(A19,REF!A:A,0)),"N.C.") -> PWMTRG_O | S19: =IFERROR(INDIRECT("REF!C"&MATCH(T19,REF!A:A,0)),"N.C.") -> KL15 | T19: 124 | V19: 53 | W19: =IFERROR(INDIRECT("REF!C"&MATCH(V19,REF!A:A,0)),"N.C.") -> GND | AN19: =IFERROR(INDIRECT("REF!C"&MATCH(AO19,REF!A:A,0)),"N.C.") -> DFUP_H | AO19: 168
A20: 10 | B20: =IFERROR(INDIRECT("REF!C"&MATCH(A20,REF!A:A,0)),"N.C.") -> VDD1V3 | S20: =IFERROR(INDIRECT("REF!C"&MATCH(T20,REF!A:A,0)),"N.C.") -> VDD1V3 | T20: 123 | V20: 54 | W20: =IFERROR(INDIRECT("REF!C"&MATCH(V20,REF!A:A,0)),"N.C.") -> VDD5_REF | AN20: =IFERROR(INDIRECT("REF!C"&MATCH(AO20,REF!A:A,0)),"N.C.") -> N.C. | AO20: 167
A21: 11 | B21: =IFERROR(INDIRECT("REF!C"&MATCH(A21,REF!A:A,0)),"N.C.") -> PWMTRG | S21: =IFERROR(INDIRECT("REF!C"&MATCH(T21,REF!A:A,0)),"N.C.") -> ESR0 | T21: 122 | V21: 55 | W21: =IFERROR(INDIRECT("REF!C"&MATCH(V21,REF!A:A,0)),"N.C.") -> MTEM2_AI | AN21: =IFERROR(INDIRECT("REF!C"&MATCH(AO21,REF!A:A,0)),"N.C.") -> N.C. | AO21: 166
A22: 12 | B22: =IFERROR(INDIRECT("REF!C"&MATCH(A22,REF!A:A,0)),"N.C.") -> N.C. | S22: =IFERROR(INDIRECT("REF!C"&MATCH(T22,REF!A:A,0)),"N.C.") -> PORST | T22: 121 | V22: 56 | W22: =IFERROR(INDIRECT("REF!C"&MATCH(V22,REF!A:A,0)),"N.C.") -> N.C. | AN22: =IFERROR(INDIRECT("REF!C"&MATCH(AO22,REF!A:A,0)),"N.C.") -> N.C. | AO22: 165
... A54: 44 | B54: =IFERROR(INDIRECT("REF!C"&MATCH(A54,REF!A:A,0)),"N.C.") -> COSL_AI | S54: =IFERROR(INDIRECT("REF!C"&MATCH(T54,REF!A:A,0)),"N.C.") -> MR | T54: 89 | V54: 88 | W54: =IFERROR(INDIRECT("REF!C"&MATCH(V54,REF!A:A,0)),"N.C.") -> N.C. | AN54: =IFERROR(INDIRECT("REF!C"&MATCH(AO54,REF!A:A,0)),"N.C.") -> CAN2TXD | AO54: 133
